Workbook

Sheet Lists
A1: ClientPriority | B1: RelationshipStatus | C1: LeadSource | D1: ProjectType | E1: FormulaOwnership | F1: YesNo | G1: YesNoPending | H1: Stage | I1: ProjectPriority | J1: WhoNeedsToAct | K1: AssignedTo | L1: GenderPositioning | M1: Concentration | N1: ProductType | O1: FragranceFamily | P1: Season | Q1: Occasion | R1: DayNight | S1: CommercialArtistic | T1: ExpenseCategory | U1: BusinessExpenseType | V1: PaymentMethod | W1: WaitingOn | X1: AgainDecision
A2: Low | B2: Lead | C2: Referral | D2: Personal Perfume | E2: Client Exclusive | F2: Yes | G2: Yes | H2: Brief | I2: Low | J2: Us | K2: =Instructions!$C$8 -> Person A | L2: Feminine | M2: Parfum / Extrait | N2: Fine Fragrance | O2: Floral | P2: Spring | Q2: Everyday | R2: Day | S2: Commercial | T2: Raw Materials | U2: Cost of Goods Sold | V2: Bank Transfer | W2: Us | X2: Yes
A3: Normal | B3: Quoted | C3: Instagram | D3: Brand Collection | E3: Perfumer Retains Rights | F3: No | G3: No | H3: Research | I3: Normal | J3: Client | K3: =Instructions!$C$9 -> Person B | L3: Masculine | M3: Eau de Parfum | N3: Home Fragrance | O3: Oriental / Amber | P3: Summer | Q3: Evening | R3: Night | S3: Artistic | T3: Alcohol/Carrier | U3: Operating Expense | V3: Card | W3: Client | X3: No
A4: High | B4: Signed | C4: Website | D4: Niche Line | E4: Shared | G4: Pending | H4: Concept Development | I4: High | J4: Third Party | K4: Both | L4: Unisex / Shared | M4: Eau de Toilette | N4: Personal Care | O4: Woody | P4: Autumn | Q4: Special Occasion | R4: Both | S4: Balanced | T4: Bottles | U4: Capital Expense | V4: PayPal | W4: Supplier | X4: Maybe
A5: VIP | B5: Active | C5: Google Search | D5: Private Label | E5: Licensed | H5: Formula Development | I5: Urgent | J5: Nobody – Complete | K5: Unassigned | L5: Not Specified | M5: Eau de Cologne | N5: Candle | O5: Fresh | P5: Winter | Q5: Office | T5: Sample Vials | V5: Stripe | W5: Nobody
B6: Completed | C6: Trade Show | D6: Corporate Gift | E6: Not Yet Agreed | H6: Compounding | M6: Fragrance Oil | N6: Diffuser | O6: Chypre | P6: All Year | Q6: Signature Scent | T6: Packaging | V6: Cash
B7: On Hold | C7: Existing Client | D7: Other | H7: Evaluation | N7: Other | O7: Fougere | T7: Labels | V7: Other
B8: Cancelled | C8: Other | H8: Sample Sent | O8: Gourmand | T8: Shipping
H9: Awaiting Feedback | O9: Aquatic | T9: Documentation
H10: Reformulation | O10: Green | T10: SDS
H11: Approved | O11: Citrus | T11: IFRA/Allergen
H12: Documentation | T12: CPSR
H13: Production | T13: Compounding
H14: Complete | T14: External Perfumer
H15: On Hold | T15: Testing
T16: Software
T17: Payment Fees
T18: Other

Sheet Dashboard
A1: PERFUMER STUDIO — Fragrance Development Dashboard
A2: ="Live view — updates automatically as you work. As of "&TEXT(TODAY(),"dddd, dd mmmm yyyy") -> Live view — updates automatically as you work. As of Monday, 17 August 2026
A4: KEY METRICS
B6: ACTIVE CLIENTS | F6: ACTIVE FRAGRANCE PROJECTS | J6: AWAITING CLIENT FEEDBACK | N6: REQUIRING ACTION FROM US | R6: APPROACHING DEADLINE (≤7D)
B7: =COUNTIF(Clients!$V$5:$V$44,"Active") -> 0 | F7: =SUMPRODUCT(('Fragrance Projects'!$A$5:$A$64<>"")*('Fragrance Projects'!$J$5:$J$64<>"Completed")*('Fragrance Projects'!$J$5:$J$64<>"On Hold")) -> 0 | J7: =COUNTIF('Fragrance Projects'!$H$5:$H$64,"Awaiting Feedback") -> 0 | N7: =COUNTIF('Fragrance Projects'!$O$5:$O$64,"Us") -> 0 | R7: =SUM('Fragrance Projects'!$AA$5:$AA$64) -> 0
B11: OVERDUE PROJECTS | F11: TOTAL CONTRACTED REVENUE | J11: REVENUE RECEIVED | N11: OUTSTANDING PAYMENTS | R11: TOTAL PROJECT EXPENSES
B12: =SUM('Fragrance Projects'!$Z$5:$Z$64) -> 0 | F12: =SUM('Project Financials'!$D$5:$D$64) -> 0 | J12: =SUM(Payments!$G$5:$G$64)+SUM(Payments!$K$5:$K$64) -> 0 | N12: =MAX(0,F12-J12) -> 0 | R12: =SUM('Expense Log'!$J$5:$J$154) -> 0
B16: ESTIMATED GROSS PROFIT | F16: AVERAGE PROFIT MARGIN % | J16: AVERAGE REVENUE PER CLIENT | N16: FORMULAS IN DEVELOPMENT | R16: APPROVED FORMULAS
B17: =F12-R12 -> 0 | F17: =IFERROR(AVERAGEIF('Project Financials'!$D$5:$D$64,">0",'Project Financials'!$AC$5:$AC$64),0) -> 0 | J17: =IFERROR(F12/B7,0) -> 0 | N17: =SUMPRODUCT(('Fragrance Projects'!$S$5:$S$64="No")*('Fragrance Projects'!$J$5:$J$64<>"Completed")*('Fragrance Projects'!$J$5:$J$64<>"On Hold")) -> 0 | R17: =COUNTIF('Fragrance Projects'!$T$5:$T$64,"Yes") -> 0
A21: URGENT ATTENTION — Needs You Now
A22: Client | B22: Fragrance | C22: Current Stage | D22: Days Remaining | E22: Next Action | F22: Why It's Flagged | G22: Assigned To
A23: =IFERROR(INDEX('Fragrance Projects'!$C$5:$C$64,SMALL('Fragrance Projects'!$AJ$5:$AJ$64,1)),"") | B23: =IFERROR(INDEX('Fragrance Projects'!$D$5:$D$64,SMALL('Fragrance Projects'!$AJ$5:$AJ$64,1)),"") | C23: =IFERROR(INDEX('Fragrance Projects'!$H$5:$H$64,SMALL('Fragrance Projects'!$AJ$5:$AJ$64,1)),"") | D23: =IFERROR(INDEX('Fragrance Projects'!$G$5:$G$64,SMALL('Fragrance Projects'!$AJ$5:$AJ$64,1)),"") | E23: =IFERROR(INDEX('Fragrance Projects'!$P$5:$P$64,SMALL('Fragrance Projects'!$AJ$5:$AJ$64,1)),"") | F23: =IFERROR(INDEX('Fragrance Projects'!$AH$5:$AH$64,SMALL('Fragrance Projects'!$AJ$5:$AJ$64,1)),"") | G23: =IFERROR(INDEX('Fragrance Projects'!$AK$5:$AK$64,SMALL('Fragrance Projects'!$AJ$5:$AJ$64,1)),"")
A24: =IFERROR(INDEX('Fragrance Projects'!$C$5:$C$64,SMALL('Fragrance Projects'!$AJ$5:$AJ$64,2)),"") | B24: =IFERROR(INDEX('Fragrance Projects'!$D$5:$D$64,SMALL('Fragrance Projects'!$AJ$5:$AJ$64,2)),"") | C24: =IFERROR(INDEX('Fragrance Projects'!$H$5:$H$64,SMALL('Fragrance Projects'!$AJ$5:$AJ$64,2)),"") | D24: =IFERROR(INDEX('Fragrance Projects'!$G$5:$G$64,SMALL('Fragrance Projects'!$AJ$5:$AJ$64,2)),"") | E24: =IFERROR(INDEX('Fragrance Projects'!$P$5:$P$64,SMALL('Fragrance Projects'!$AJ$5:$AJ$64,2)),"") | F24: =IFERROR(INDEX('Fragrance Projects'!$AH$5:$AH$64,SMALL('Fragrance Projects'!$AJ$5:$AJ$64,2)),"") | G24: =IFERROR(INDEX('Fragrance Projects'!$AK$5:$AK$64,SMALL('Fragrance Projects'!$AJ$5:$AJ$64,2)),"")
A25: =IFERROR(INDEX('Fragrance Projects'!$C$5:$C$64,SMALL('Fragrance Projects'!$AJ$5:$AJ$64,3)),"") | B25: =IFERROR(INDEX('Fragrance Projects'!$D$5:$D$64,SMALL('Fragrance Projects'!$AJ$5:$AJ$64,3)),"") | C25: =IFERROR(INDEX('Fragrance Projects'!$H$5:$H$64,SMALL('Fragrance Projects'!$AJ$5:$AJ$64,3)),"") | D25: =IFERROR(INDEX('Fragrance Projects'!$G$5:$G$64,SMALL('Fragrance Projects'!$AJ$5:$AJ$64,3)),"") | E25: =IFERROR(INDEX('Fragrance Projects'!$P$5:$P$64,SMALL('Fragrance Projects'!$AJ$5:$AJ$64,3)),"") | F25: =IFERROR(INDEX('Fragrance Projects'!$AH$5:$AH$64,SMALL('Fragrance Projects'!$AJ$5:$AJ$64,3)),"") | G25: =IFERROR(INDEX('Fragrance Projects'!$AK$5:$AK$64,SMALL('Fragrance Projects'!$AJ$5:$AJ$64,3)),"")
A26: =IFERROR(INDEX('Fragrance Projects'!$C$5:$C$64,SMALL('Fragrance Projects'!$AJ$5:$AJ$64,4)),"") | B26: =IFERROR(INDEX('Fragrance Projects'!$D$5:$D$64,SMALL('Fragrance Projects'!$AJ$5:$AJ$64,4)),"") | C26: =IFERROR(INDEX('Fragrance Projects'!$H$5:$H$64,SMALL('Fragrance Projects'!$AJ$5:$AJ$64,4)),"") | D26: =IFERROR(INDEX('Fragrance Projects'!$G$5:$G$64,SMALL('Fragrance Projects'!$AJ$5:$AJ$64,4)),"") | E26: =IFERROR(INDEX('Fragrance Projects'!$P$5:$P$64,SMALL('Fragrance Projects'!$AJ$5:$AJ$64,4)),"") | F26: =IFERROR(INDEX('Fragrance Projects'!$AH$5:$AH$64,SMALL('Fragrance Projects'!$AJ$5:$AJ$64,4)),"") | G26: =IFERROR(INDEX('Fragrance Projects'!$AK$5:$AK$64,SMALL('Fragrance Projects'!$AJ$5:$AJ$64,4)),"")
A27: =IFERROR(INDEX('Fragrance Projects'!$C$5:$C$64,SMALL('Fragrance Projects'!$AJ$5:$AJ$64,5)),"") | B27: =IFERROR(INDEX('Fragrance Projects'!$D$5:$D$64,SMALL('Fragrance Projects'!$AJ$5:$AJ$64,5)),"") | C27: =IFERROR(INDEX('Fragrance Projects'!$H$5:$H$64,SMALL('Fragrance Projects'!$AJ$5:$AJ$64,5)),"") | D27: =IFERROR(INDEX('Fragrance Projects'!$G$5:$G$64,SMALL('Fragrance Projects'!$AJ$5:$AJ$64,5)),"") | E27: =IFERROR(INDEX('Fragrance Projects'!$P$5:$P$64,SMALL('Fragrance Projects'!$AJ$5:$AJ$64,5)),"") | F27: =IFERROR(INDEX('Fragrance Projects'!$AH$5:$AH$64,SMALL('Fragrance Projects'!$AJ$5:$AJ$64,5)),"") | G27: =IFERROR(INDEX('Fragrance Projects'!$AK$5:$AK$64,SMALL('Fragrance Projects'!$AJ$5:$AJ$64,5)),"")
A28: =IFERROR(INDEX('Fragrance Projects'!$C$5:$C$64,SMALL('Fragrance Projects'!$AJ$5:$AJ$64,6)),"") | B28: =IFERROR(INDEX('Fragrance Projects'!$D$5:$D$64,SMALL('Fragrance Projects'!$AJ$5:$AJ$64,6)),"") | C28: =IFERROR(INDEX('Fragrance Projects'!$H$5:$H$64,SMALL('Fragrance Projects'!$AJ$5:$AJ$64,6)),"") | D28: =IFERROR(INDEX('Fragrance Projects'!$G$5:$G$64,SMALL('Fragrance Projects'!$AJ$5:$AJ$64,6)),"") | E28: =IFERROR(INDEX('Fragrance Projects'!$P$5:$P$64,SMALL('Fragrance Projects'!$AJ$5:$AJ$64,6)),"") | F28: =IFERROR(INDEX('Fragrance Projects'!$AH$5:$AH$64,SMALL('Fragrance Projects'!$AJ$5:$AJ$64,6)),"") | G28: =IFERROR(INDEX('Fragrance Projects'!$AK$5:$AK$64,SMALL('Fragrance Projects'!$AJ$5:$AJ$64,6)),"")
A29: =IFERROR(INDEX('Fragrance Projects'!$C$5:$C$64,SMALL('Fragrance Projects'!$AJ$5:$AJ$64,7)),"") | B29: =IFERROR(INDEX('Fragrance Projects'!$D$5:$D$64,SMALL('Fragrance Projects'!$AJ$5:$AJ$64,7)),"") | C29: =IFERROR(INDEX('Fragrance Projects'!$H$5:$H$64,SMALL('Fragrance Projects'!$AJ$5:$AJ$64,7)),"") | D29: =IFERROR(INDEX('Fragrance Projects'!$G$5:$G$64,SMALL('Fragrance Projects'!$AJ$5:$AJ$64,7)),"") | E29: =IFERROR(INDEX('Fragrance Projects'!$P$5:$P$64,SMALL('Fragrance Projects'!$AJ$5:$AJ$64,7)),"") | F29: =IFERROR(INDEX('Fragrance Projects'!$AH$5:$AH$64,SMALL('Fragrance Projects'!$AJ$5:$AJ$64,7)),"") | G29: =IFERROR(INDEX('Fragrance Projects'!$AK$5:$AK$64,SMALL('Fragrance Projects'!$AJ$5:$AJ$64,7)),"")
A30: =IFERROR(INDEX('Fragrance Projects'!$C$5:$C$64,SMALL('Fragrance Projects'!$AJ$5:$AJ$64,8)),"") | B30: =IFERROR(INDEX('Fragrance Projects'!$D$5:$D$64,SMALL('Fragrance Projects'!$AJ$5:$AJ$64,8)),"") | C30: =IFERROR(INDEX('Fragrance Projects'!$H$5:$H$64,SMALL('Fragrance Projects'!$AJ$5:$AJ$64,8)),"") | D30: =IFERROR(INDEX('Fragrance Projects'!$G$5:$G$64,SMALL('Fragrance Projects'!$AJ$5:$AJ$64,8)),"") | E30: =IFERROR(INDEX('Fragrance Projects'!$P$5:$P$64,SMALL('Fragrance Projects'!$AJ$5:$AJ$64,8)),"") | F30: =IFERROR(INDEX('Fragrance Projects'!$AH$5:$AH$64,SMALL('Fragrance Projects'!$AJ$5:$AJ$64,8)),"") | G30: =IFERROR(INDEX('Fragrance Projects'!$AK$5:$AK$64,SMALL('Fragrance Projects'!$AJ$5:$AJ$64,8)),"")
A31: =IFERROR(INDEX('Fragrance Projects'!$C$5:$C$64,SMALL('Fragrance Projects'!$AJ$5:$AJ$64,9)),"") | B31: =IFERROR(INDEX('Fragrance Projects'!$D$5:$D$64,SMALL('Fragrance Projects'!$AJ$5:$AJ$64,9)),"") | C31: =IFERROR(INDEX('Fragrance Projects'!$H$5:$H$64,SMALL('Fragrance Projects'!$AJ$5:$AJ$64,9)),"") | D31: =IFERROR(INDEX('Fragrance Projects'!$G$5:$G$64,SMALL('Fragrance Projects'!$AJ$5:$AJ$64,9)),"") | E31: =IFERROR(INDEX('Fragrance Projects'!$P$5:$P$64,SMALL('Fragrance Projects'!$AJ$5:$AJ$64,9)),"") | F31: =IFERROR(INDEX('Fragrance Projects'!$AH$5:$AH$64,SMALL('Fragrance Projects'!$AJ$5:$AJ$64,9)),"") | G31: =IFERROR(INDEX('Fragrance Projects'!$AK$5:$AK$64,SMALL('Fragrance Projects'!$AJ$5:$AJ$64,9)),"")
A32: =IFERROR(INDEX('Fragrance Projects'!$C$5:$C$64,SMALL('Fragrance Projects'!$AJ$5:$AJ$64,10)),"") | B32: =IFERROR(INDEX('Fragrance Projects'!$D$5:$D$64,SMALL('Fragrance Projects'!$AJ$5:$AJ$64,10)),"") | C32: =IFERROR(INDEX('Fragrance Projects'!$H$5:$H$64,SMALL('Fragrance Projects'!$AJ$5:$AJ$64,10)),"") | D32: =IFERROR(INDEX('Fragrance Projects'!$G$5:$G$64,SMALL('Fragrance Projects'!$AJ$5:$AJ$64,10)),"") | E32: =IFERROR(INDEX('Fragrance Projects'!$P$5:$P$64,SMALL('Fragrance Projects'!$AJ$5:$AJ$64,10)),"") | F32: =IFERROR(INDEX('Fragrance Projects'!$AH$5:$AH$64,SMALL('Fragrance Projects'!$AJ$5:$AJ$64,10)),"") | G32: =IFERROR(INDEX('Fragrance Projects'!$AK$5:$AK$64,SMALL('Fragrance Projects'!$AJ$5:$AJ$64,10)),"")
A34: UPCOMING DEADLINES — Next 8 In Line
A35: Client | B35: Fragrance | C35: Deadline | D35: Days Remaining | E35: Current Stage | F35: Next Action
A36: =IFERROR(INDEX('Fragrance Projects'!$C$5:$C$64,MOD(SMALL('Fragrance Projects'!$AI$5:$AI$64,1),1000)),"") | B36: =IFERROR(INDEX('Fragrance Projects'!$D$5:$D$64,MOD(SMALL('Fragrance Projects'!$AI$5:$AI$64,1),1000)),"") | C36: =IFERROR(INDEX('Fragrance Projects'!$F$5:$F$64,MOD(SMALL('Fragrance Projects'!$AI$5:$AI$64,1),1000)),"") | D36: =IFERROR(INDEX('Fragrance Projects'!$G$5:$G$64,MOD(SMALL('Fragrance Projects'!$AI$5:$AI$64,1),1000)),"") | E36: =IFERROR(INDEX('Fragrance Projects'!$H$5:$H$64,MOD(SMALL('Fragrance Projects'!$AI$5:$AI$64,1),1000)),"") | F36: =IFERROR(INDEX('Fragrance Projects'!$P$5:$P$64,MOD(SMALL('Fragrance Projects'!$AI$5:$AI$64,1),1000)),"")
A37: =IFERROR(INDEX('Fragrance Projects'!$C$5:$C$64,MOD(SMALL('Fragrance Projects'!$AI$5:$AI$64,2),1000)),"") | B37: =IFERROR(INDEX('Fragrance Projects'!$D$5:$D$64,MOD(SMALL('Fragrance Projects'!$AI$5:$AI$64,2),1000)),"") | C37: =IFERROR(INDEX('Fragrance Projects'!$F$5:$F$64,MOD(SMALL('Fragrance Projects'!$AI$5:$AI$64,2),1000)),"") | D37: =IFERROR(INDEX('Fragrance Projects'!$G$5:$G$64,MOD(SMALL('Fragrance Projects'!$AI$5:$AI$64,2),1000)),"") | E37: =IFERROR(INDEX('Fragrance Projects'!$H$5:$H$64,MOD(SMALL('Fragrance Projects'!$AI$5:$AI$64,2),1000)),"") | F37: =IFERROR(INDEX('Fragrance Projects'!$P$5:$P$64,MOD(SMALL('Fragrance Projects'!$AI$5:$AI$64,2),1000)),"")
A38: =IFERROR(INDEX('Fragrance Projects'!$C$5:$C$64,MOD(SMALL('Fragrance Projects'!$AI$5:$AI$64,3),1000)),"") | B38: =IFERROR(INDEX('Fragrance Projects'!$D$5:$D$64,MOD(SMALL('Fragrance Projects'!$AI$5:$AI$64,3),1000)),"") | C38: =IFERROR(INDEX('Fragrance Projects'!$F$5:$F$64,MOD(SMALL('Fragrance Projects'!$AI$5:$AI$64,3),1000)),"") | D38: =IFERROR(INDEX('Fragrance Projects'!$G$5:$G$64,MOD(SMALL('Fragrance Projects'!$AI$5:$AI$64,3),1000)),"") | E38: =IFERROR(INDEX('Fragrance Projects'!$H$5:$H$64,MOD(SMALL('Fragrance Projects'!$AI$5:$AI$64,3),1000)),"") | F38: =IFERROR(INDEX('Fragrance Projects'!$P$5:$P$64,MOD(SMALL('Fragrance Projects'!$AI$5:$AI$64,3),1000)),"")
A39: =IFERROR(INDEX('Fragrance Projects'!$C$5:$C$64,MOD(SMALL('Fragrance Projects'!$AI$5:$AI$64,4),1000)),"") | B39: =IFERROR(INDEX('Fragrance Projects'!$D$5:$D$64,MOD(SMALL('Fragrance Projects'!$AI$5:$AI$64,4),1000)),"") | C39: =IFERROR(INDEX('Fragrance Projects'!$F$5:$F$64,MOD(SMALL('Fragrance Projects'!$AI$5:$AI$64,4),1000)),"") | D39: =IFERROR(INDEX('Fragrance Projects'!$G$5:$G$64,MOD(SMALL('Fragrance Projects'!$AI$5:$AI$64,4),1000)),"") | E39: =IFERROR(INDEX('Fragrance Projects'!$H$5:$H$64,MOD(SMALL('Fragrance Projects'!$AI$5:$AI$64,4),1000)),"") | F39: =IFERROR(INDEX('Fragrance Projects'!$P$5:$P$64,MOD(SMALL('Fragrance Projects'!$AI$5:$AI$64,4),1000)),"")
A40: =IFERROR(INDEX('Fragrance Projects'!$C$5:$C$64,MOD(SMALL('Fragrance Projects'!$AI$5:$AI$64,5),1000)),"") | B40: =IFERROR(INDEX('Fragrance Projects'!$D$5:$D$64,MOD(SMALL('Fragrance Projects'!$AI$5:$AI$64,5),1000)),"") | C40: =IFERROR(INDEX('Fragrance Projects'!$F$5:$F$64,MOD(SMALL('Fragrance Projects'!$AI$5:$AI$64,5),1000)),"") | D40: =IFERROR(INDEX('Fragrance Projects'!$G$5:$G$64,MOD(SMALL('Fragrance Projects'!$AI$5:$AI$64,5),1000)),"") | E40: =IFERROR(INDEX('Fragrance Projects'!$H$5:$H$64,MOD(SMALL('Fragrance Projects'!$AI$5:$AI$64,5),1000)),"") | F40: =IFERROR(INDEX('Fragrance Projects'!$P$5:$P$64,MOD(SMALL('Fragrance Projects'!$AI$5:$AI$64,5),1000)),"")
A41: =IFERROR(INDEX('Fragrance Projects'!$C$5:$C$64,MOD(SMALL('Fragrance Projects'!$AI$5:$AI$64,6),1000)),"") | B41: =IFERROR(INDEX('Fragrance Projects'!$D$5:$D$64,MOD(SMALL('Fragrance Projects'!$AI$5:$AI$64,6),1000)),"") | C41: =IFERROR(INDEX('Fragrance Projects'!$F$5:$F$64,MOD(SMALL('Fragrance Projects'!$AI$5:$AI$64,6),1000)),"") | D41: =IFERROR(INDEX('Fragrance Projects'!$G$5:$G$64,MOD(SMALL('Fragrance Projects'!$AI$5:$AI$64,6),1000)),"") | E41: =IFERROR(INDEX('Fragrance Projects'!$H$5:$H$64,MOD(SMALL('Fragrance Projects'!$AI$5:$AI$64,6),1000)),"") | F41: =IFERROR(INDEX('Fragrance Projects'!$P$5:$P$64,MOD(SMALL('Fragrance Projects'!$AI$5:$AI$64,6),1000)),"")
A42: =IFERROR(INDEX('Fragrance Projects'!$C$5:$C$64,MOD(SMALL('Fragrance Projects'!$AI$5:$AI$64,7),1000)),"") | B42: =IFERROR(INDEX('Fragrance Projects'!$D$5:$D$64,MOD(SMALL('Fragrance Projects'!$AI$5:$AI$64,7),1000)),"") | C42: =IFERROR(INDEX('Fragrance Projects'!$F$5:$F$64,MOD(SMALL('Fragrance Projects'!$AI$5:$AI$64,7),1000)),"") | D42: =IFERROR(INDEX('Fragrance Projects'!$G$5:$G$64,MOD(SMALL('Fragrance Projects'!$AI$5:$AI$64,7),1000)),"") | E42: =IFERROR(INDEX('Fragrance Projects'!$H$5:$H$64,MOD(SMALL('Fragrance Projects'!$AI$5:$AI$64,7),1000)),"") | F42: =IFERROR(INDEX('Fragrance Projects'!$P$5:$P$64,MOD(SMALL('Fragrance Projects'!$AI$5:$AI$64,7),1000)),"")
A43: =IFERROR(INDEX('Fragrance Projects'!$C$5:$C$64,MOD(SMALL('Fragrance Projects'!$AI$5:$AI$64,8),1000)),"") | B43: =IFERROR(INDEX('Fragrance Projects'!$D$5:$D$64,MOD(SMALL('Fragrance Projects'!$AI$5:$AI$64,8),1000)),"") | C43: =IFERROR(INDEX('Fragrance Projects'!$F$5:$F$64,MOD(SMALL('Fragrance Projects'!$AI$5:$AI$64,8),1000)),"") | D43: =IFERROR(INDEX('Fragrance Projects'!$G$5:$G$64,MOD(SMALL('Fragrance Projects'!$AI$5:$AI$64,8),1000)),"") | E43: =IFERROR(INDEX('Fragrance Projects'!$H$5:$H$64,MOD(SMALL('Fragrance Projects'!$AI$5:$AI$64,8),1000)),"") | F43: =IFERROR(INDEX('Fragrance Projects'!$P$5:$P$64,MOD(SMALL('Fragrance Projects'!$AI$5:$AI$64,8),1000)),"")
A45: CHARTS
A46: Chart data (calculated automatically — do not edit)
A47: Month | B47: Revenue Received | C47: Expenses | D47: Profit | F47: Stage | G47: Projects | I47: Client | J47: Active Projects
A48: =TEXT(DATE(YEAR(EDATE(TODAY(),-7)),MONTH(EDATE(TODAY(),-7)),1),"mmm yy") -> Jan 26 | B48: =SUMIFS(Payments!$G$5:$G$64,Payments!$H$5:$H$64,">="&DATE(YEAR(EDATE(TODAY(),-7)),MONTH(EDATE(TODAY(),-7)),1),Payments!$H$5:$H$64,"<="&EDATE(DATE(YEAR(EDATE(TODAY(),-7)),MONTH(EDATE(TODAY(),-7)),1),1)-1)+SUMIFS(Payments!$K$5:$K$64,Payments!$J$5:$J$64,">="&DATE(YEAR(EDATE(TODAY(),-7)),MONTH(EDATE(TODAY(),-7)),1),Payments!$J$5:$J$64,"<="&EDATE(DATE(YEAR(EDATE(TODAY(),-7)),MONTH(EDATE(TODAY(),-7)),1),1)-1) -> 0 | C48: =SUMIFS('Expense Log'!$J$5:$J$154,'Expense Log'!$A$5:$A$154,">="&DATE(YEAR(EDATE(TODAY(),-7)),MONTH(EDATE(TODAY(),-7)),1),'Expense Log'!$A$5:$A$154,"<="&EDATE(DATE(YEAR(EDATE(TODAY(),-7)),MONTH(EDATE(TODAY(),-7)),1),1)-1) -> 0 | D48: =B48-C48 -> 0 | F48: Brief | G48: =COUNTIF('Fragrance Projects'!$H$5:$H$64,"Brief") -> 0 | I48: =IFERROR(INDEX(Clients!$B$5:$B$44,1),"") -> 0 | J48: =IF($I48="","",SUMPRODUCT(('Fragrance Projects'!$C$5:$C$64=$I48)*('Fragrance Projects'!$J$5:$J$64<>"Completed")*('Fragrance Projects'!$J$5:$J$64<>"On Hold")))
A49: =TEXT(DATE(YEAR(EDATE(TODAY(),-6)),MONTH(EDATE(TODAY(),-6)),1),"mmm yy") -> Feb 26 | B49: =SUMIFS(Payments!$G$5:$G$64,Payments!$H$5:$H$64,">="&DATE(YEAR(EDATE(TODAY(),-6)),MONTH(EDATE(TODAY(),-6)),1),Payments!$H$5:$H$64,"<="&EDATE(DATE(YEAR(EDATE(TODAY(),-6)),MONTH(EDATE(TODAY(),-6)),1),1)-1)+SUMIFS(Payments!$K$5:$K$64,Payments!$J$5:$J$64,">="&DATE(YEAR(EDATE(TODAY(),-6)),MONTH(EDATE(TODAY(),-6)),1),Payments!$J$5:$J$64,"<="&EDATE(DATE(YEAR(EDATE(TODAY(),-6)),MONTH(EDATE(TODAY(),-6)),1),1)-1) -> 0 | C49: =SUMIFS('Expense Log'!$J$5:$J$154,'Expense Log'!$A$5:$A$154,">="&DATE(YEAR(EDATE(TODAY(),-6)),MONTH(EDATE(TODAY(),-6)),1),'Expense Log'!$A$5:$A$154,"<="&EDATE(DATE(YEAR(EDATE(TODAY(),-6)),MONTH(EDATE(TODAY(),-6)),1),1)-1) -> 0 | D49: =B49-C49 -> 0 | F49: Research | G49: =COUNTIF('Fragrance Projects'!$H$5:$H$64,"Research") -> 0 | I49: =IFERROR(INDEX(Clients!$B$5:$B$44,2),"") -> 0 | J49: =IF($I49="","",SUMPRODUCT(('Fragrance Projects'!$C$5:$C$64=$I49)*('Fragrance Projects'!$J$5:$J$64<>"Completed")*('Fragrance Projects'!$J$5:$J$64<>"On Hold")))
A50: =TEXT(DATE(YEAR(EDATE(TODAY(),-5)),MONTH(EDATE(TODAY(),-5)),1),"mmm yy") -> Mar 26 | B50: =SUMIFS(Payments!$G$5:$G$64,Payments!$H$5:$H$64,">="&DATE(YEAR(EDATE(TODAY(),-5)),MONTH(EDATE(TODAY(),-5)),1),Payments!$H$5:$H$64,"<="&EDATE(DATE(YEAR(EDATE(TODAY(),-5)),MONTH(EDATE(TODAY(),-5)),1),1)-1)+SUMIFS(Payments!$K$5:$K$64,Payments!$J$5:$J$64,">="&DATE(YEAR(EDATE(TODAY(),-5)),MONTH(EDATE(TODAY(),-5)),1),Payments!$J$5:$J$64,"<="&EDATE(DATE(YEAR(EDATE(TODAY(),-5)),MONTH(EDATE(TODAY(),-5)),1),1)-1) -> 0 | C50: =SUMIFS('Expense Log'!$J$5:$J$154,'Expense Log'!$A$5:$A$154,">="&DATE(YEAR(EDATE(TODAY(),-5)),MONTH(EDATE(TODAY(),-5)),1),'Expense Log'!$A$5:$A$154,"<="&EDATE(DATE(YEAR(EDATE(TODAY(),-5)),MONTH(EDATE(TODAY(),-5)),1),1)-1) -> 0 | D50: =B50-C50 -> 0 | F50: Concept Development | G50: =COUNTIF('Fragrance Projects'!$H$5:$H$64,"Concept Development") -> 0 | I50: =IFERROR(INDEX(Clients!$B$5:$B$44,3),"") -> 0 | J50: =IF($I50="","",SUMPRODUCT(('Fragrance Projects'!$C$5:$C$64=$I50)*('Fragrance Projects'!$J$5:$J$64<>"Completed")*('Fragrance Projects'!$J$5:$J$64<>"On Hold")))
A51: =TEXT(DATE(YEAR(EDATE(TODAY(),-4)),MONTH(EDATE(TODAY(),-4)),1),"mmm yy") -> Apr 26 | B51: =SUMIFS(Payments!$G$5:$G$64,Payments!$H$5:$H$64,">="&DATE(YEAR(EDATE(TODAY(),-4)),MONTH(EDATE(TODAY(),-4)),1),Payments!$H$5:$H$64,"<="&EDATE(DATE(YEAR(EDATE(TODAY(),-4)),MONTH(EDATE(TODAY(),-4)),1),1)-1)+SUMIFS(Payments!$K$5:$K$64,Payments!$J$5:$J$64,">="&DATE(YEAR(EDATE(TODAY(),-4)),MONTH(EDATE(TODAY(),-4)),1),Payments!$J$5:$J$64,"<="&EDATE(DATE(YEAR(EDATE(TODAY(),-4)),MONTH(EDATE(TODAY(),-4)),1),1)-1) -> 0 | C51: =SUMIFS('Expense Log'!$J$5:$J$154,'Expense Log'!$A$5:$A$154,">="&DATE(YEAR(EDATE(TODAY(),-4)),MONTH(EDATE(TODAY(),-4)),1),'Expense Log'!$A$5:$A$154,"<="&EDATE(DATE(YEAR(EDATE(TODAY(),-4)),MONTH(EDATE(TODAY(),-4)),1),1)-1) -> 0 | D51: =B51-C51 -> 0 | F51: Formula Development | G51: =COUNTIF('Fragrance Projects'!$H$5:$H$64,"Formula Development") -> 0 | I51: =IFERROR(INDEX(Clients!$B$5:$B$44,4),"") -> 0 | J51: =IF($I51="","",SUMPRODUCT(('Fragrance Projects'!$C$5:$C$64=$I51)*('Fragrance Projects'!$J$5:$J$64<>"Completed")*('Fragrance Projects'!$J$5:$J$64<>"On Hold")))
A52: =TEXT(DATE(YEAR(EDATE(TODAY(),-3)),MONTH(EDATE(TODAY(),-3)),1),"mmm yy") -> May 26 | B52: =SUMIFS(Payments!$G$5:$G$64,Payments!$H$5:$H$64,">="&DATE(YEAR(EDATE(TODAY(),-3)),MONTH(EDATE(TODAY(),-3)),1),Payments!$H$5:$H$64,"<="&EDATE(DATE(YEAR(EDATE(TODAY(),-3)),MONTH(EDATE(TODAY(),-3)),1),1)-1)+SUMIFS(Payments!$K$5:$K$64,Payments!$J$5:$J$64,">="&DATE(YEAR(EDATE(TODAY(),-3)),MONTH(EDATE(TODAY(),-3)),1),Payments!$J$5:$J$64,"<="&EDATE(DATE(YEAR(EDATE(TODAY(),-3)),MONTH(EDATE(TODAY(),-3)),1),1)-1) -> 0 | C52: =SUMIFS('Expense Log'!$J$5:$J$154,'Expense Log'!$A$5:$A$154,">="&DATE(YEAR(EDATE(TODAY(),-3)),MONTH(EDATE(TODAY(),-3)),1),'Expense Log'!$A$5:$A$154,"<="&EDATE(DATE(YEAR(EDATE(TODAY(),-3)),MONTH(EDATE(TODAY(),-3)),1),1)-1) -> 0 | D52: =B52-C52 -> 0 | F52: Compounding | G52: =COUNTIF('Fragrance Projects'!$H$5:$H$64,"Compounding") -> 0 | I52: =IFERROR(INDEX(Clients!$B$5:$B$44,5),"") -> 0 | J52: =IF($I52="","",SUMPRODUCT(('Fragrance Projects'!$C$5:$C$64=$I52)*('Fragrance Projects'!$J$5:$J$64<>"Completed")*('Fragrance Projects'!$J$5:$J$64<>"On Hold")))
A53: =TEXT(DATE(YEAR(EDATE(TODAY(),-2)),MONTH(EDATE(TODAY(),-2)),1),"mmm yy") -> Jun 26 | B53: =SUMIFS(Payments!$G$5:$G$64,Payments!$H$5:$H$64,">="&DATE(YEAR(EDATE(TODAY(),-2)),MONTH(EDATE(TODAY(),-2)),1),Payments!$H$5:$H$64,"<="&EDATE(DATE(YEAR(EDATE(TODAY(),-2)),MONTH(EDATE(TODAY(),-2)),1),1)-1)+SUMIFS(Payments!$K$5:$K$64,Payments!$J$5:$J$64,">="&DATE(YEAR(EDATE(TODAY(),-2)),MONTH(EDATE(TODAY(),-2)),1),Payments!$J$5:$J$64,"<="&EDATE(DATE(YEAR(EDATE(TODAY(),-2)),MONTH(EDATE(TODAY(),-2)),1),1)-1) -> 0 | C53: =SUMIFS('Expense Log'!$J$5:$J$154,'Expense Log'!$A$5:$A$154,">="&DATE(YEAR(EDATE(TODAY(),-2)),MONTH(EDATE(TODAY(),-2)),1),'Expense Log'!$A$5:$A$154,"<="&EDATE(DATE(YEAR(EDATE(TODAY(),-2)),MONTH(EDATE(TODAY(),-2)),1),1)-1) -> 0 | D53: =B53-C53 -> 0 | F53: Evaluation | G53: =COUNTIF('Fragrance Projects'!$H$5:$H$64,"Evaluation") -> 0 | I53: =IFERROR(INDEX(Clients!$B$5:$B$44,6),"") -> 0 | J53: =IF($I53="","",SUMPRODUCT(('Fragrance Projects'!$C$5:$C$64=$I53)*('Fragrance Projects'!$J$5:$J$64<>"Completed")*('Fragrance Projects'!$J$5:$J$64<>"On Hold")))
...

Sheet Clients
A1: CLIENTS — Master Client Database
A2: One row per client / brand. New clients: add a row and choose the next Client ID (e.g. C007).
B3: INPUT — type or choose here | F3: CALCULATED — formula, do not edit | J3: AUTO-LOOKUP — pulled from another sheet
A4: Client ID | B4: Client / Brand Name | C4: Contact Name | D4: Email | E4: Phone | F4: Country | G4: Date Enquired | H4: Date Signed | I4: Lead Source | J4: Project Type | K4: No. of Fragrances | L4: Package Purchased | M4: Agreed Price | N4: Deposit Required | O4: Deposit Paid | P4: Remaining Balance | Q4: Payment Status | R4: Contract Signed? | S4: NDA? | T4: Formula Ownership | U4: Client Priority | V4: Relationship Status | W4: Notes
P5: =IF($M5="","",$M5-$O5) | Q5: =IF($A5="","",_xlfn.IFS($M5=0,"Not Invoiced",$O5=0,"Awaiting Deposit",$P5<=0,"Paid",TRUE(),"Part Paid"))
P6: =IF($M6="","",$M6-$O6) | Q6: =IF($A6="","",_xlfn.IFS($M6=0,"Not Invoiced",$O6=0,"Awaiting Deposit",$P6<=0,"Paid",TRUE(),"Part Paid"))
P7: =IF($M7="","",$M7-$O7) | Q7: =IF($A7="","",_xlfn.IFS($M7=0,"Not Invoiced",$O7=0,"Awaiting Deposit",$P7<=0,"Paid",TRUE(),"Part Paid"))
P8: =IF($M8="","",$M8-$O8) | Q8: =IF($A8="","",_xlfn.IFS($M8=0,"Not Invoiced",$O8=0,"Awaiting Deposit",$P8<=0,"Paid",TRUE(),"Part Paid"))
P9: =IF($M9="","",$M9-$O9) | Q9: =IF($A9="","",_xlfn.IFS($M9=0,"Not Invoiced",$O9=0,"Awaiting Deposit",$P9<=0,"Paid",TRUE(),"Part Paid"))
P10: =IF($M10="","",$M10-$O10) | Q10: =IF($A10="","",_xlfn.IFS($M10=0,"Not Invoiced",$O10=0,"Awaiting Deposit",$P10<=0,"Paid",TRUE(),"Part Paid"))
P11: =IF($M11="","",$M11-$O11) | Q11: =IF($A11="","",_xlfn.IFS($M11=0,"Not Invoiced",$O11=0,"Awaiting Deposit",$P11<=0,"Paid",TRUE(),"Part Paid"))
P12: =IF($M12="","",$M12-$O12) | Q12: =IF($A12="","",_xlfn.IFS($M12=0,"Not Invoiced",$O12=0,"Awaiting Deposit",$P12<=0,"Paid",TRUE(),"Part Paid"))
P13: =IF($M13="","",$M13-$O13) | Q13: =IF($A13="","",_xlfn.IFS($M13=0,"Not Invoiced",$O13=0,"Awaiting Deposit",$P13<=0,"Paid",TRUE(),"Part Paid"))
P14: =IF($M14="","",$M14-$O14) | Q14: =IF($A14="","",_xlfn.IFS($M14=0,"Not Invoiced",$O14=0,"Awaiting Deposit",$P14<=0,"Paid",TRUE(),"Part Paid"))
P15: =IF($M15="","",$M15-$O15) | Q15: =IF($A15="","",_xlfn.IFS($M15=0,"Not Invoiced",$O15=0,"Awaiting Deposit",$P15<=0,"Paid",TRUE(),"Part Paid"))
P16: =IF($M16="","",$M16-$O16) | Q16: =IF($A16="","",_xlfn.IFS($M16=0,"Not Invoiced",$O16=0,"Awaiting Deposit",$P16<=0,"Paid",TRUE(),"Part Paid"))
... P44: =IF($M44="","",$M44-$O44) | Q44: =IF($A44="","",_xlfn.IFS($M44=0,"Not Invoiced",$O44=0,"Awaiting Deposit",$P44<=0,"Paid",TRUE(),"Part Paid"))

Sheet Fragrance Projects
A1: FRAGRANCE PROJECTS — Development Tracker
A2: One row per fragrance. Overall Status, iteration count and staleness flags are calculated automatically.
B3: INPUT — type or choose here | F3: CALCULATED — formula, do not edit | J3: AUTO-LOOKUP — pulled from another sheet
A4: Project ID | B4: Client ID | C4: Client Name | D4: Fragrance Name / Working Name | E4: Project Start Date | F4: Target Completion Date | G4: Days Remaining | H4: Current Stage | I4: Priority | J4: Overall Status | K4: Current Iteration | L4: Included Iterations | M4: Remaining Iterations | N4: Last Action Date | O4: Who Currently Needs to Act? | P4: Next Action | Q4: Next Action Due | R4: Days Since Last Activity | S4: Formula Complete? | T4: Formula Approved? | U4: Documentation Complete? | V4: Production/Compounding Required? | W4: Final Delivery Complete? | X4: Notes | Y4: Spacer | Z4: Overdue Flag | AA4: Due Soon Flag | AB4: Waiting On Us Flag | AC4: Client Feedback Overdue Flag | AD4: Iteration Limit Flag | AE4: Low Margin Flag | AF4: Unpaid Flag | AG4: Urgent Flag | AH4: Urgent Reason | AI4: Deadline Rank | AJ4: Urgent Row Offset | AK4: Assigned To
C5: =IFERROR(INDEX(Clients!$B$5:$B$44,MATCH($B5,Clients!$A$5:$A$44,0)),"") | G5: =IF($A5="","",$F5-TODAY()) | J5: =IF($A5="","",_xlfn.IFS(OR($W5="Yes",$H5="Complete"),"Completed",$H5="On Hold","On Hold",$G5<0,"Overdue",$O5="Client","Waiting on Client",$G5<=7,"At Risk",TRUE(),"On Track")) | K5: =IF($A5="","",IFERROR(_xlfn.MAXIFS('Iteration Tracker'!$D$5:$D$124,'Iteration Tracker'!$A$5:$A$124,$A5),0)) | M5: =IF($A5="","",$L5-$K5) | R5: =IF($A5="","",IF($N5="","",TODAY()-$N5)) | Z5: =IF($A5="",0,IF(AND($G5<0,$J5<>"Completed",$J5<>"On Hold"),1,0)) -> 0 | AA5: =IF($A5="",0,IF(AND($G5>=0,$G5<=7,$J5<>"Completed",$J5<>"On Hold"),1,0)) -> 0 | AB5: =IF($A5="",0,IF(AND($O5="Us",$J5<>"Completed"),1,0)) -> 0 | AC5: =IF($A5="",0,IF(AND($H5="Awaiting Feedback",$R5<>"",$R5>7),1,0)) -> 0 | AD5: =IF($A5="",0,IF(AND($M5<>"",$M5<=1,$J5<>"Completed"),1,0)) -> 0 | AE5: =IFERROR(IF(AND($A5<>"",INDEX('Project Financials'!$AC$5:$AC$64,MATCH($A5,'Project Financials'!$A$5:$A$64,0))<0.2,INDEX('Project Financials'!$D$5:$D$64,MATCH($A5,'Project Financials'!$A$5:$A$64,0))>0),1,0),0) -> 0 | AF5: =IFERROR(IF(OR(INDEX(Payments!$N$5:$N$64,MATCH($A5,Payments!$B$5:$B$64,0))="Overdue",INDEX(Payments!$N$5:$N$64,MATCH($A5,Payments!$B$5:$B$64,0))="Awaiting Deposit"),1,0),0) -> 0 | AG5: =IF($A5="",0,IF(SUM(Z5:AF5)>0,1,0)) -> 0 | AH5: =IF($AG5=0,"",LEFT((IF($Z5=1,"Overdue; ",""))&(IF($AA5=1,"Deadline ≤ 7 days; ",""))&(IF($AB5=1,"Action needed from us; ",""))&(IF($AC5=1,"Client feedback overdue; ",""))&(IF($AD5=1,"At iteration limit; ",""))&(IF($AE5=1,"Low margin; ",""))&(IF($AF5=1,"Unpaid invoice; ","")),LEN((IF($Z5=1,"Overdue; ",""))&(IF($AA5=1,"Deadline ≤ 7 days; ",""))&(IF($AB5=1,"Action needed from us; ",""))&(IF($AC5=1,"Client feedback overdue; ",""))&(IF($AD5=1,"At iteration limit; ",""))&(IF($AE5=1,"Low margin; ",""))&(IF($AF5=1,"Unpaid invoice; ","")))-2)) | AI5: =IF(AND($A5<>"",$J5<>"Completed",$J5<>"On Hold"),$F5*1000+(ROW()-ROW($A$5)+1),"") | AJ5: =IF($AG5=1,ROW()-ROW($A$5)+1,"")
C6: =IFERROR(INDEX(Clients!$B$5:$B$44,MATCH($B6,Clients!$A$5:$A$44,0)),"") | G6: =IF($A6="","",$F6-TODAY()) | J6: =IF($A6="","",_xlfn.IFS(OR($W6="Yes",$H6="Complete"),"Completed",$H6="On Hold","On Hold",$G6<0,"Overdue",$O6="Client","Waiting on Client",$G6<=7,"At Risk",TRUE(),"On Track")) | K6: =IF($A6="","",IFERROR(_xlfn.MAXIFS('Iteration Tracker'!$D$5:$D$124,'Iteration Tracker'!$A$5:$A$124,$A6),0)) | M6: =IF($A6="","",$L6-$K6) | R6: =IF($A6="","",IF($N6="","",TODAY()-$N6)) | Z6: =IF($A6="",0,IF(AND($G6<0,$J6<>"Completed",$J6<>"On Hold"),1,0)) -> 0 | AA6: =IF($A6="",0,IF(AND($G6>=0,$G6<=7,$J6<>"Completed",$J6<>"On Hold"),1,0)) -> 0 | AB6: =IF($A6="",0,IF(AND($O6="Us",$J6<>"Completed"),1,0)) -> 0 | AC6: =IF($A6="",0,IF(AND($H6="Awaiting Feedback",$R6<>"",$R6>7),1,0)) -> 0 | AD6: =IF($A6="",0,IF(AND($M6<>"",$M6<=1,$J6<>"Completed"),1,0)) -> 0 | AE6: =IFERROR(IF(AND($A6<>"",INDEX('Project Financials'!$AC$5:$AC$64,MATCH($A6,'Project Financials'!$A$5:$A$64,0))<0.2,INDEX('Project Financials'!$D$5:$D$64,MATCH($A6,'Project Financials'!$A$5:$A$64,0))>0),1,0),0) -> 0 | AF6: =IFERROR(IF(OR(INDEX(Payments!$N$5:$N$64,MATCH($A6,Payments!$B$5:$B$64,0))="Overdue",INDEX(Payments!$N$5:$N$64,MATCH($A6,Payments!$B$5:$B$64,0))="Awaiting Deposit"),1,0),0) -> 0 | AG6: =IF($A6="",0,IF(SUM(Z6:AF6)>0,1,0)) -> 0 | AH6: =IF($AG6=0,"",LEFT((IF($Z6=1,"Overdue; ",""))&(IF($AA6=1,"Deadline ≤ 7 days; ",""))&(IF($AB6=1,"Action needed from us; ",""))&(IF($AC6=1,"Client feedback overdue; ",""))&(IF($AD6=1,"At iteration limit; ",""))&(IF($AE6=1,"Low margin; ",""))&(IF($AF6=1,"Unpaid invoice; ","")),LEN((IF($Z6=1,"Overdue; ",""))&(IF($AA6=1,"Deadline ≤ 7 days; ",""))&(IF($AB6=1,"Action needed from us; ",""))&(IF($AC6=1,"Client feedback overdue; ",""))&(IF($AD6=1,"At iteration limit; ",""))&(IF($AE6=1,"Low margin; ",""))&(IF($AF6=1,"Unpaid invoice; ","")))-2)) | AI6: =IF(AND($A6<>"",$J6<>"Completed",$J6<>"On Hold"),$F6*1000+(ROW()-ROW($A$5)+1),"") | AJ6: =IF($AG6=1,ROW()-ROW($A$5)+1,"")
C7: =IFERROR(INDEX(Clients!$B$5:$B$44,MATCH($B7,Clients!$A$5:$A$44,0)),"") | G7: =IF($A7="","",$F7-TODAY()) | J7: =IF($A7="","",_xlfn.IFS(OR($W7="Yes",$H7="Complete"),"Completed",$H7="On Hold","On Hold",$G7<0,"Overdue",$O7="Client","Waiting on Client",$G7<=7,"At Risk",TRUE(),"On Track")) | K7: =IF($A7="","",IFERROR(_xlfn.MAXIFS('Iteration Tracker'!$D$5:$D$124,'Iteration Tracker'!$A$5:$A$124,$A7),0)) | M7: =IF($A7="","",$L7-$K7) | R7: =IF($A7="","",IF($N7="","",TODAY()-$N7)) | Z7: =IF($A7="",0,IF(AND($G7<0,$J7<>"Completed",$J7<>"On Hold"),1,0)) -> 0 | AA7: =IF($A7="",0,IF(AND($G7>=0,$G7<=7,$J7<>"Completed",$J7<>"On Hold"),1,0)) -> 0 | AB7: =IF($A7="",0,IF(AND($O7="Us",$J7<>"Completed"),1,0)) -> 0 | AC7: =IF($A7="",0,IF(AND($H7="Awaiting Feedback",$R7<>"",$R7>7),1,0)) -> 0 | AD7: =IF($A7="",0,IF(AND($M7<>"",$M7<=1,$J7<>"Completed"),1,0)) -> 0 | AE7: =IFERROR(IF(AND($A7<>"",INDEX('Project Financials'!$AC$5:$AC$64,MATCH($A7,'Project Financials'!$A$5:$A$64,0))<0.2,INDEX('Project Financials'!$D$5:$D$64,MATCH($A7,'Project Financials'!$A$5:$A$64,0))>0),1,0),0) -> 0 | AF7: =IFERROR(IF(OR(INDEX(Payments!$N$5:$N$64,MATCH($A7,Payments!$B$5:$B$64,0))="Overdue",INDEX(Payments!$N$5:$N$64,MATCH($A7,Payments!$B$5:$B$64,0))="Awaiting Deposit"),1,0),0) -> 0 | AG7: =IF($A7="",0,IF(SUM(Z7:AF7)>0,1,0)) -> 0 | AH7: =IF($AG7=0,"",LEFT((IF($Z7=1,"Overdue; ",""))&(IF($AA7=1,"Deadline ≤ 7 days; ",""))&(IF($AB7=1,"Action needed from us; ",""))&(IF($AC7=1,"Client feedback overdue; ",""))&(IF($AD7=1,"At iteration limit; ",""))&(IF($AE7=1,"Low margin; ",""))&(IF($AF7=1,"Unpaid invoice; ","")),LEN((IF($Z7=1,"Overdue; ",""))&(IF($AA7=1,"Deadline ≤ 7 days; ",""))&(IF($AB7=1,"Action needed from us; ",""))&(IF($AC7=1,"Client feedback overdue; ",""))&(IF($AD7=1,"At iteration limit; ",""))&(IF($AE7=1,"Low margin; ",""))&(IF($AF7=1,"Unpaid invoice; ","")))-2)) | AI7: =IF(AND($A7<>"",$J7<>"Completed",$J7<>"On Hold"),$F7*1000+(ROW()-ROW($A$5)+1),"") | AJ7: =IF($AG7=1,ROW()-ROW($A$5)+1,"")
C8: =IFERROR(INDEX(Clients!$B$5:$B$44,MATCH($B8,Clients!$A$5:$A$44,0)),"") | G8: =IF($A8="","",$F8-TODAY()) | J8: =IF($A8="","",_xlfn.IFS(OR($W8="Yes",$H8="Complete"),"Completed",$H8="On Hold","On Hold",$G8<0,"Overdue",$O8="Client","Waiting on Client",$G8<=7,"At Risk",TRUE(),"On Track")) | K8: =IF($A8="","",IFERROR(_xlfn.MAXIFS('Iteration Tracker'!$D$5:$D$124,'Iteration Tracker'!$A$5:$A$124,$A8),0)) | M8: =IF($A8="","",$L8-$K8) | R8: =IF($A8="","",IF($N8="","",TODAY()-$N8)) | Z8: =IF($A8="",0,IF(AND($G8<0,$J8<>"Completed",$J8<>"On Hold"),1,0)) -> 0 | AA8: =IF($A8="",0,IF(AND($G8>=0,$G8<=7,$J8<>"Completed",$J8<>"On Hold"),1,0)) -> 0 | AB8: =IF($A8="",0,IF(AND($O8="Us",$J8<>"Completed"),1,0)) -> 0 | AC8: =IF($A8="",0,IF(AND($H8="Awaiting Feedback",$R8<>"",$R8>7),1,0)) -> 0 | AD8: =IF($A8="",0,IF(AND($M8<>"",$M8<=1,$J8<>"Completed"),1,0)) -> 0 | AE8: =IFERROR(IF(AND($A8<>"",INDEX('Project Financials'!$AC$5:$AC$64,MATCH($A8,'Project Financials'!$A$5:$A$64,0))<0.2,INDEX('Project Financials'!$D$5:$D$64,MATCH($A8,'Project Financials'!$A$5:$A$64,0))>0),1,0),0) -> 0 | AF8: =IFERROR(IF(OR(INDEX(Payments!$N$5:$N$64,MATCH($A8,Payments!$B$5:$B$64,0))="Overdue",INDEX(Payments!$N$5:$N$64,MATCH($A8,Payments!$B$5:$B$64,0))="Awaiting Deposit"),1,0),0) -> 0 | AG8: =IF($A8="",0,IF(SUM(Z8:AF8)>0,1,0)) -> 0 | AH8: =IF($AG8=0,"",LEFT((IF($Z8=1,"Overdue; ",""))&(IF($AA8=1,"Deadline ≤ 7 days; ",""))&(IF($AB8=1,"Action needed from us; ",""))&(IF($AC8=1,"Client feedback overdue; ",""))&(IF($AD8=1,"At iteration limit; ",""))&(IF($AE8=1,"Low margin; ",""))&(IF($AF8=1,"Unpaid invoice; ","")),LEN((IF($Z8=1,"Overdue; ",""))&(IF($AA8=1,"Deadline ≤ 7 days; ",""))&(IF($AB8=1,"Action needed from us; ",""))&(IF($AC8=1,"Client feedback overdue; ",""))&(IF($AD8=1,"At iteration limit; ",""))&(IF($AE8=1,"Low margin; ",""))&(IF($AF8=1,"Unpaid invoice; ","")))-2)) | AI8: =IF(AND($A8<>"",$J8<>"Completed",$J8<>"On Hold"),$F8*1000+(ROW()-ROW($A$5)+1),"") | AJ8: =IF($AG8=1,ROW()-ROW($A$5)+1,"")
C9: =IFERROR(INDEX(Clients!$B$5:$B$44,MATCH($B9,Clients!$A$5:$A$44,0)),"") | G9: =IF($A9="","",$F9-TODAY()) | J9: =IF($A9="","",_xlfn.IFS(OR($W9="Yes",$H9="Complete"),"Completed",$H9="On Hold","On Hold",$G9<0,"Overdue",$O9="Client","Waiting on Client",$G9<=7,"At Risk",TRUE(),"On Track")) | K9: =IF($A9="","",IFERROR(_xlfn.MAXIFS('Iteration Tracker'!$D$5:$D$124,'Iteration Tracker'!$A$5:$A$124,$A9),0)) | M9: =IF($A9="","",$L9-$K9) | R9: =IF($A9="","",IF($N9="","",TODAY()-$N9)) | Z9: =IF($A9="",0,IF(AND($G9<0,$J9<>"Completed",$J9<>"On Hold"),1,0)) -> 0 | AA9: =IF($A9="",0,IF(AND($G9>=0,$G9<=7,$J9<>"Completed",$J9<>"On Hold"),1,0)) -> 0 | AB9: =IF($A9="",0,IF(AND($O9="Us",$J9<>"Completed"),1,0)) -> 0 | AC9: =IF($A9="",0,IF(AND($H9="Awaiting Feedback",$R9<>"",$R9>7),1,0)) -> 0 | AD9: =IF($A9="",0,IF(AND($M9<>"",$M9<=1,$J9<>"Completed"),1,0)) -> 0 | AE9: =IFERROR(IF(AND($A9<>"",INDEX('Project Financials'!$AC$5:$AC$64,MATCH($A9,'Project Financials'!$A$5:$A$64,0))<0.2,INDEX('Project Financials'!$D$5:$D$64,MATCH($A9,'Project Financials'!$A$5:$A$64,0))>0),1,0),0) -> 0 | AF9: =IFERROR(IF(OR(INDEX(Payments!$N$5:$N$64,MATCH($A9,Payments!$B$5:$B$64,0))="Overdue",INDEX(Payments!$N$5:$N$64,MATCH($A9,Payments!$B$5:$B$64,0))="Awaiting Deposit"),1,0),0) -> 0 | AG9: =IF($A9="",0,IF(SUM(Z9:AF9)>0,1,0)) -> 0 | AH9: =IF($AG9=0,"",LEFT((IF($Z9=1,"Overdue; ",""))&(IF($AA9=1,"Deadline ≤ 7 days; ",""))&(IF($AB9=1,"Action needed from us; ",""))&(IF($AC9=1,"Client feedback overdue; ",""))&(IF($AD9=1,"At iteration limit; ",""))&(IF($AE9=1,"Low margin; ",""))&(IF($AF9=1,"Unpaid invoice; ","")),LEN((IF($Z9=1,"Overdue; ",""))&(IF($AA9=1,"Deadline ≤ 7 days; ",""))&(IF($AB9=1,"Action needed from us; ",""))&(IF($AC9=1,"Client feedback overdue; ",""))&(IF($AD9=1,"At iteration limit; ",""))&(IF($AE9=1,"Low margin; ",""))&(IF($AF9=1,"Unpaid invoice; ","")))-2)) | AI9: =IF(AND($A9<>"",$J9<>"Completed",$J9<>"On Hold"),$F9*1000+(ROW()-ROW($A$5)+1),"") | AJ9: =IF($AG9=1,ROW()-ROW($A$5)+1,"")
C10: =IFERROR(INDEX(Clients!$B$5:$B$44,MATCH($B10,Clients!$A$5:$A$44,0)),"") | G10: =IF($A10="","",$F10-TODAY()) | J10: =IF($A10="","",_xlfn.IFS(OR($W10="Yes",$H10="Complete"),"Completed",$H10="On Hold","On Hold",$G10<0,"Overdue",$O10="Client","Waiting on Client",$G10<=7,"At Risk",TRUE(),"On Track")) | K10: =IF($A10="","",IFERROR(_xlfn.MAXIFS('Iteration Tracker'!$D$5:$D$124,'Iteration Tracker'!$A$5:$A$124,$A10),0)) | M10: =IF($A10="","",$L10-$K10) | R10: =IF($A10="","",IF($N10="","",TODAY()-$N10)) | Z10: =IF($A10="",0,IF(AND($G10<0,$J10<>"Completed",$J10<>"On Hold"),1,0)) -> 0 | AA10: =IF($A10="",0,IF(AND($G10>=0,$G10<=7,$J10<>"Completed",$J10<>"On Hold"),1,0)) -> 0 | AB10: =IF($A10="",0,IF(AND($O10="Us",$J10<>"Completed"),1,0)) -> 0 | AC10: =IF($A10="",0,IF(AND($H10="Awaiting Feedback",$R10<>"",$R10>7),1,0)) -> 0 | AD10: =IF($A10="",0,IF(AND($M10<>"",$M10<=1,$J10<>"Completed"),1,0)) -> 0 | AE10: =IFERROR(IF(AND($A10<>"",INDEX('Project Financials'!$AC$5:$AC$64,MATCH($A10,'Project Financials'!$A$5:$A$64,0))<0.2,INDEX('Project Financials'!$D$5:$D$64,MATCH($A10,'Project Financials'!$A$5:$A$64,0))>0),1,0),0) -> 0 | AF10: =IFERROR(IF(OR(INDEX(Payments!$N$5:$N$64,MATCH($A10,Payments!$B$5:$B$64,0))="Overdue",INDEX(Payments!$N$5:$N$64,MATCH($A10,Payments!$B$5:$B$64,0))="Awaiting Deposit"),1,0),0) -> 0 | AG10: =IF($A10="",0,IF(SUM(Z10:AF10)>0,1,0)) -> 0 | AH10: =IF($AG10=0,"",LEFT((IF($Z10=1,"Overdue; ",""))&(IF($AA10=1,"Deadline ≤ 7 days; ",""))&(IF($AB10=1,"Action needed from us; ",""))&(IF($AC10=1,"Client feedback overdue; ",""))&(IF($AD10=1,"At iteration limit; ",""))&(IF($AE10=1,"Low margin; ",""))&(IF($AF10=1,"Unpaid invoice; ","")),LEN((IF($Z10=1,"Overdue; ",""))&(IF($AA10=1,"Deadline ≤ 7 days; ",""))&(IF($AB10=1,"Action needed from us; ",""))&(IF($AC10=1,"Client feedback overdue; ",""))&(IF($AD10=1,"At iteration limit; ",""))&(IF($AE10=1,"Low margin; ",""))&(IF($AF10=1,"Unpaid invoice; ","")))-2)) | AI10: =IF(AND($A10<>"",$J10<>"Completed",$J10<>"On Hold"),$F10*1000+(ROW()-ROW($A$5)+1),"") | AJ10: =IF($AG10=1,ROW()-ROW($A$5)+1,"")
C11: =IFERROR(INDEX(Clients!$B$5:$B$44,MATCH($B11,Clients!$A$5:$A$44,0)),"") | G11: =IF($A11="","",$F11-TODAY()) | J11: =IF($A11="","",_xlfn.IFS(OR($W11="Yes",$H11="Complete"),"Completed",$H11="On Hold","On Hold",$G11<0,"Overdue",$O11="Client","Waiting on Client",$G11<=7,"At Risk",TRUE(),"On Track")) | K11: =IF($A11="","",IFERROR(_xlfn.MAXIFS('Iteration Tracker'!$D$5:$D$124,'Iteration Tracker'!$A$5:$A$124,$A11),0)) | M11: =IF($A11="","",$L11-$K11) | R11: =IF($A11="","",IF($N11="","",TODAY()-$N11)) | Z11: =IF($A11="",0,IF(AND($G11<0,$J11<>"Completed",$J11<>"On Hold"),1,0)) -> 0 | AA11: =IF($A11="",0,IF(AND($G11>=0,$G11<=7,$J11<>"Completed",$J11<>"On Hold"),1,0)) -> 0 | AB11: =IF($A11="",0,IF(AND($O11="Us",$J11<>"Completed"),1,0)) -> 0 | AC11: =IF($A11="",0,IF(AND($H11="Awaiting Feedback",$R11<>"",$R11>7),1,0)) -> 0 | AD11: =IF($A11="",0,IF(AND($M11<>"",$M11<=1,$J11<>"Completed"),1,0)) -> 0 | AE11: =IFERROR(IF(AND($A11<>"",INDEX('Project Financials'!$AC$5:$AC$64,MATCH($A11,'Project Financials'!$A$5:$A$64,0))<0.2,INDEX('Project Financials'!$D$5:$D$64,MATCH($A11,'Project Financials'!$A$5:$A$64,0))>0),1,0),0) -> 0 | AF11: =IFERROR(IF(OR(INDEX(Payments!$N$5:$N$64,MATCH($A11,Payments!$B$5:$B$64,0))="Overdue",INDEX(Payments!$N$5:$N$64,MATCH($A11,Payments!$B$5:$B$64,0))="Awaiting Deposit"),1,0),0) -> 0 | AG11: =IF($A11="",0,IF(SUM(Z11:AF11)>0,1,0)) -> 0 | AH11: =IF($AG11=0,"",LEFT((IF($Z11=1,"Overdue; ",""))&(IF($AA11=1,"Deadline ≤ 7 days; ",""))&(IF($AB11=1,"Action needed from us; ",""))&(IF($AC11=1,"Client feedback overdue; ",""))&(IF($AD11=1,"At iteration limit; ",""))&(IF($AE11=1,"Low margin; ",""))&(IF($AF11=1,"Unpaid invoice; ","")),LEN((IF($Z11=1,"Overdue; ",""))&(IF($AA11=1,"Deadline ≤ 7 days; ",""))&(IF($AB11=1,"Action needed from us; ",""))&(IF($AC11=1,"Client feedback overdue; ",""))&(IF($AD11=1,"At iteration limit; ",""))&(IF($AE11=1,"Low margin; ",""))&(IF($AF11=1,"Unpaid invoice; ","")))-2)) | AI11: =IF(AND($A11<>"",$J11<>"Completed",$J11<>"On Hold"),$F11*1000+(ROW()-ROW($A$5)+1),"") | AJ11: =IF($AG11=1,ROW()-ROW($A$5)+1,"")
C12: =IFERROR(INDEX(Clients!$B$5:$B$44,MATCH($B12,Clients!$A$5:$A$44,0)),"") | G12: =IF($A12="","",$F12-TODAY()) | J12: =IF($A12="","",_xlfn.IFS(OR($W12="Yes",$H12="Complete"),"Completed",$H12="On Hold","On Hold",$G12<0,"Overdue",$O12="Client","Waiting on Client",$G12<=7,"At Risk",TRUE(),"On Track")) | K12: =IF($A12="","",IFERROR(_xlfn.MAXIFS('Iteration Tracker'!$D$5:$D$124,'Iteration Tracker'!$A$5:$A$124,$A12),0)) | M12: =IF($A12="","",$L12-$K12) | R12: =IF($A12="","",IF($N12="","",TODAY()-$N12)) | Z12: =IF($A12="",0,IF(AND($G12<0,$J12<>"Completed",$J12<>"On Hold"),1,0)) -> 0 | AA12: =IF($A12="",0,IF(AND($G12>=0,$G12<=7,$J12<>"Completed",$J12<>"On Hold"),1,0)) -> 0 | AB12: =IF($A12="",0,IF(AND($O12="Us",$J12<>"Completed"),1,0)) -> 0 | AC12: =IF($A12="",0,IF(AND($H12="Awaiting Feedback",$R12<>"",$R12>7),1,0)) -> 0 | AD12: =IF($A12="",0,IF(AND($M12<>"",$M12<=1,$J12<>"Completed"),1,0)) -> 0 | AE12: =IFERROR(IF(AND($A12<>"",INDEX('Project Financials'!$AC$5:$AC$64,MATCH($A12,'Project Financials'!$A$5:$A$64,0))<0.2,INDEX('Project Financials'!$D$5:$D$64,MATCH($A12,'Project Financials'!$A$5:$A$64,0))>0),1,0),0) -> 0 | AF12: =IFERROR(IF(OR(INDEX(Payments!$N$5:$N$64,MATCH($A12,Payments!$B$5:$B$64,0))="Overdue",INDEX(Payments!$N$5:$N$64,MATCH($A12,Payments!$B$5:$B$64,0))="Awaiting Deposit"),1,0),0) -> 0 | AG12: =IF($A12="",0,IF(SUM(Z12:AF12)>0,1,0)) -> 0 | AH12: =IF($AG12=0,"",LEFT((IF($Z12=1,"Overdue; ",""))&(IF($AA12=1,"Deadline ≤ 7 days; ",""))&(IF($AB12=1,"Action needed from us; ",""))&(IF($AC12=1,"Client feedback overdue; ",""))&(IF($AD12=1,"At iteration limit; ",""))&(IF($AE12=1,"Low margin; ",""))&(IF($AF12=1,"Unpaid invoice; ","")),LEN((IF($Z12=1,"Overdue; ",""))&(IF($AA12=1,"Deadline ≤ 7 days; ",""))&(IF($AB12=1,"Action needed from us; ",""))&(IF($AC12=1,"Client feedback overdue; ",""))&(IF($AD12=1,"At iteration limit; ",""))&(IF($AE12=1,"Low margin; ",""))&(IF($AF12=1,"Unpaid invoice; ","")))-2)) | AI12: =IF(AND($A12<>"",$J12<>"Completed",$J12<>"On Hold"),$F12*1000+(ROW()-ROW($A$5)+1),"") | AJ12: =IF($AG12=1,ROW()-ROW($A$5)+1,"")
C13: =IFERROR(INDEX(Clients!$B$5:$B$44,MATCH($B13,Clients!$A$5:$A$44,0)),"") | G13: =IF($A13="","",$F13-TODAY()) | J13: =IF($A13="","",_xlfn.IFS(OR($W13="Yes",$H13="Complete"),"Completed",$H13="On Hold","On Hold",$G13<0,"Overdue",$O13="Client","Waiting on Client",$G13<=7,"At Risk",TRUE(),"On Track")) | K13: =IF($A13="","",IFERROR(_xlfn.MAXIFS('Iteration Tracker'!$D$5:$D$124,'Iteration Tracker'!$A$5:$A$124,$A13),0)) | M13: =IF($A13="","",$L13-$K13) | R13: =IF($A13="","",IF($N13="","",TODAY()-$N13)) | Z13: =IF($A13="",0,IF(AND($G13<0,$J13<>"Completed",$J13<>"On Hold"),1,0)) -> 0 | AA13: =IF($A13="",0,IF(AND($G13>=0,$G13<=7,$J13<>"Completed",$J13<>"On Hold"),1,0)) -> 0 | AB13: =IF($A13="",0,IF(AND($O13="Us",$J13<>"Completed"),1,0)) -> 0 | AC13: =IF($A13="",0,IF(AND($H13="Awaiting Feedback",$R13<>"",$R13>7),1,0)) -> 0 | AD13: =IF($A13="",0,IF(AND($M13<>"",$M13<=1,$J13<>"Completed"),1,0)) -> 0 | AE13: =IFERROR(IF(AND($A13<>"",INDEX('Project Financials'!$AC$5:$AC$64,MATCH($A13,'Project Financials'!$A$5:$A$64,0))<0.2,INDEX('Project Financials'!$D$5:$D$64,MATCH($A13,'Project Financials'!$A$5:$A$64,0))>0),1,0),0) -> 0 | AF13: =IFERROR(IF(OR(INDEX(Payments!$N$5:$N$64,MATCH($A13,Payments!$B$5:$B$64,0))="Overdue",INDEX(Payments!$N$5:$N$64,MATCH($A13,Payments!$B$5:$B$64,0))="Awaiting Deposit"),1,0),0) -> 0 | AG13: =IF($A13="",0,IF(SUM(Z13:AF13)>0,1,0)) -> 0 | AH13: =IF($AG13=0,"",LEFT((IF($Z13=1,"Overdue; ",""))&(IF($AA13=1,"Deadline ≤ 7 days; ",""))&(IF($AB13=1,"Action needed from us; ",""))&(IF($AC13=1,"Client feedback overdue; ",""))&(IF($AD13=1,"At iteration limit; ",""))&(IF($AE13=1,"Low margin; ",""))&(IF($AF13=1,"Unpaid invoice; ","")),LEN((IF($Z13=1,"Overdue; ",""))&(IF($AA13=1,"Deadline ≤ 7 days; ",""))&(IF($AB13=1,"Action needed from us; ",""))&(IF($AC13=1,"Client feedback overdue; ",""))&(IF($AD13=1,"At iteration limit; ",""))&(IF($AE13=1,"Low margin; ",""))&(IF($AF13=1,"Unpaid invoice; ","")))-2)) | AI13: =IF(AND($A13<>"",$J13<>"Completed",$J13<>"On Hold"),$F13*1000+(ROW()-ROW($A$5)+1),"") | AJ13: =IF($AG13=1,ROW()-ROW($A$5)+1,"")
C14: =IFERROR(INDEX(Clients!$B$5:$B$44,MATCH($B14,Clients!$A$5:$A$44,0)),"") | G14: =IF($A14="","",$F14-TODAY()) | J14: =IF($A14="","",_xlfn.IFS(OR($W14="Yes",$H14="Complete"),"Completed",$H14="On Hold","On Hold",$G14<0,"Overdue",$O14="Client","Waiting on Client",$G14<=7,"At Risk",TRUE(),"On Track")) | K14: =IF($A14="","",IFERROR(_xlfn.MAXIFS('Iteration Tracker'!$D$5:$D$124,'Iteration Tracker'!$A$5:$A$124,$A14),0)) | M14: =IF($A14="","",$L14-$K14) | R14: =IF($A14="","",IF($N14="","",TODAY()-$N14)) | Z14: =IF($A14="",0,IF(AND($G14<0,$J14<>"Completed",$J14<>"On Hold"),1,0)) -> 0 | AA14: =IF($A14="",0,IF(AND($G14>=0,$G14<=7,$J14<>"Completed",$J14<>"On Hold"),1,0)) -> 0 | AB14: =IF($A14="",0,IF(AND($O14="Us",$J14<>"Completed"),1,0)) -> 0 | AC14: =IF($A14="",0,IF(AND($H14="Awaiting Feedback",$R14<>"",$R14>7),1,0)) -> 0 | AD14: =IF($A14="",0,IF(AND($M14<>"",$M14<=1,$J14<>"Completed"),1,0)) -> 0 | AE14: =IFERROR(IF(AND($A14<>"",INDEX('Project Financials'!$AC$5:$AC$64,MATCH($A14,'Project Financials'!$A$5:$A$64,0))<0.2,INDEX('Project Financials'!$D$5:$D$64,MATCH($A14,'Project Financials'!$A$5:$A$64,0))>0),1,0),0) -> 0 | AF14: =IFERROR(IF(OR(INDEX(Payments!$N$5:$N$64,MATCH($A14,Payments!$B$5:$B$64,0))="Overdue",INDEX(Payments!$N$5:$N$64,MATCH($A14,Payments!$B$5:$B$64,0))="Awaiting Deposit"),1,0),0) -> 0 | AG14: =IF($A14="",0,IF(SUM(Z14:AF14)>0,1,0)) -> 0 | AH14: =IF($AG14=0,"",LEFT((IF($Z14=1,"Overdue; ",""))&(IF($AA14=1,"Deadline ≤ 7 days; ",""))&(IF($AB14=1,"Action needed from us; ",""))&(IF($AC14=1,"Client feedback overdue; ",""))&(IF($AD14=1,"At iteration limit; ",""))&(IF($AE14=1,"Low margin; ",""))&(IF($AF14=1,"Unpaid invoice; ","")),LEN((IF($Z14=1,"Overdue; ",""))&(IF($AA14=1,"Deadline ≤ 7 days; ",""))&(IF($AB14=1,"Action needed from us; ",""))&(IF($AC14=1,"Client feedback overdue; ",""))&(IF($AD14=1,"At iteration limit; ",""))&(IF($AE14=1,"Low margin; ",""))&(IF($AF14=1,"Unpaid invoice; ","")))-2)) | AI14: =IF(AND($A14<>"",$J14<>"Completed",$J14<>"On Hold"),$F14*1000+(ROW()-ROW($A$5)+1),"") | AJ14: =IF($AG14=1,ROW()-ROW($A$5)+1,"")
C15: =IFERROR(INDEX(Clients!$B$5:$B$44,MATCH($B15,Clients!$A$5:$A$44,0)),"") | G15: =IF($A15="","",$F15-TODAY()) | J15: =IF($A15="","",_xlfn.IFS(OR($W15="Yes",$H15="Complete"),"Completed",$H15="On Hold","On Hold",$G15<0,"Overdue",$O15="Client","Waiting on Client",$G15<=7,"At Risk",TRUE(),"On Track")) | K15: =IF($A15="","",IFERROR(_xlfn.MAXIFS('Iteration Tracker'!$D$5:$D$124,'Iteration Tracker'!$A$5:$A$124,$A15),0)) | M15: =IF($A15="","",$L15-$K15) | R15: =IF($A15="","",IF($N15="","",TODAY()-$N15)) | Z15: =IF($A15="",0,IF(AND($G15<0,$J15<>"Completed",$J15<>"On Hold"),1,0)) -> 0 | AA15: =IF($A15="",0,IF(AND($G15>=0,$G15<=7,$J15<>"Completed",$J15<>"On Hold"),1,0)) -> 0 | AB15: =IF($A15="",0,IF(AND($O15="Us",$J15<>"Completed"),1,0)) -> 0 | AC15: =IF($A15="",0,IF(AND($H15="Awaiting Feedback",$R15<>"",$R15>7),1,0)) -> 0 | AD15: =IF($A15="",0,IF(AND($M15<>"",$M15<=1,$J15<>"Completed"),1,0)) -> 0 | AE15: =IFERROR(IF(AND($A15<>"",INDEX('Project Financials'!$AC$5:$AC$64,MATCH($A15,'Project Financials'!$A$5:$A$64,0))<0.2,INDEX('Project Financials'!$D$5:$D$64,MATCH($A15,'Project Financials'!$A$5:$A$64,0))>0),1,0),0) -> 0 | AF15: =IFERROR(IF(OR(INDEX(Payments!$N$5:$N$64,MATCH($A15,Payments!$B$5:$B$64,0))="Overdue",INDEX(Payments!$N$5:$N$64,MATCH($A15,Payments!$B$5:$B$64,0))="Awaiting Deposit"),1,0),0) -> 0 | AG15: =IF($A15="",0,IF(SUM(Z15:AF15)>0,1,0)) -> 0 | AH15: =IF($AG15=0,"",LEFT((IF($Z15=1,"Overdue; ",""))&(IF($AA15=1,"Deadline ≤ 7 days; ",""))&(IF($AB15=1,"Action needed from us; ",""))&(IF($AC15=1,"Client feedback overdue; ",""))&(IF($AD15=1,"At iteration limit; ",""))&(IF($AE15=1,"Low margin; ",""))&(IF($AF15=1,"Unpaid invoice; ","")),LEN((IF($Z15=1,"Overdue; ",""))&(IF($AA15=1,"Deadline ≤ 7 days; ",""))&(IF($AB15=1,"Action needed from us; ",""))&(IF($AC15=1,"Client feedback overdue; ",""))&(IF($AD15=1,"At iteration limit; ",""))&(IF($AE15=1,"Low margin; ",""))&(IF($AF15=1,"Unpaid invoice; ","")))-2)) | AI15: =IF(AND($A15<>"",$J15<>"Completed",$J15<>"On Hold"),$F15*1000+(ROW()-ROW($A$5)+1),"") | AJ15: =IF($AG15=1,ROW()-ROW($A$5)+1,"")
C16: =IFERROR(INDEX(Clients!$B$5:$B$44,MATCH($B16,Clients!$A$5:$A$44,0)),"") | G16: =IF($A16="","",$F16-TODAY()) | J16: =IF($A16="","",_xlfn.IFS(OR($W16="Yes",$H16="Complete"),"Completed",$H16="On Hold","On Hold",$G16<0,"Overdue",$O16="Client","Waiting on Client",$G16<=7,"At Risk",TRUE(),"On Track")) | K16: =IF($A16="","",IFERROR(_xlfn.MAXIFS('Iteration Tracker'!$D$5:$D$124,'Iteration Tracker'!$A$5:$A$124,$A16),0)) | M16: =IF($A16="","",$L16-$K16) | R16: =IF($A16="","",IF($N16="","",TODAY()-$N16)) | Z16: =IF($A16="",0,IF(AND($G16<0,$J16<>"Completed",$J16<>"On Hold"),1,0)) -> 0 | AA16: =IF($A16="",0,IF(AND($G16>=0,$G16<=7,$J16<>"Completed",$J16<>"On Hold"),1,0)) -> 0 | AB16: =IF($A16="",0,IF(AND($O16="Us",$J16<>"Completed"),1,0)) -> 0 | AC16: =IF($A16="",0,IF(AND($H16="Awaiting Feedback",$R16<>"",$R16>7),1,0)) -> 0 | AD16: =IF($A16="",0,IF(AND($M16<>"",$M16<=1,$J16<>"Completed"),1,0)) -> 0 | AE16: =IFERROR(IF(AND($A16<>"",INDEX('Project Financials'!$AC$5:$AC$64,MATCH($A16,'Project Financials'!$A$5:$A$64,0))<0.2,INDEX('Project Financials'!$D$5:$D$64,MATCH($A16,'Project Financials'!$A$5:$A$64,0))>0),1,0),0) -> 0 | AF16: =IFERROR(IF(OR(INDEX(Payments!$N$5:$N$64,MATCH($A16,Payments!$B$5:$B$64,0))="Overdue",INDEX(Payments!$N$5:$N$64,MATCH($A16,Payments!$B$5:$B$64,0))="Awaiting Deposit"),1,0),0) -> 0 | AG16: =IF($A16="",0,IF(SUM(Z16:AF16)>0,1,0)) -> 0 | AH16: =IF($AG16=0,"",LEFT((IF($Z16=1,"Overdue; ",""))&(IF($AA16=1,"Deadline ≤ 7 days; ",""))&(IF($AB16=1,"Action needed from us; ",""))&(IF($AC16=1,"Client feedback overdue; ",""))&(IF($AD16=1,"At iteration limit; ",""))&(IF($AE16=1,"Low margin; ",""))&(IF($AF16=1,"Unpaid invoice; ","")),LEN((IF($Z16=1,"Overdue; ",""))&(IF($AA16=1,"Deadline ≤ 7 days; ",""))&(IF($AB16=1,"Action needed from us; ",""))&(IF($AC16=1,"Client feedback overdue; ",""))&(IF($AD16=1,"At iteration limit; ",""))&(IF($AE16=1,"Low margin; ",""))&(IF($AF16=1,"Unpaid invoice; ","")))-2)) | AI16: =IF(AND($A16<>"",$J16<>"Completed",$J16<>"On Hold"),$F16*1000+(ROW()-ROW($A$5)+1),"") | AJ16: =IF($AG16=1,ROW()-ROW($A$5)+1,"")
... C64: =IFERROR(INDEX(Clients!$B$5:$B$44,MATCH($B64,Clients!$A$5:$A$44,0)),"") | G64: =IF($A64="","",$F64-TODAY()) | J64: =IF($A64="","",_xlfn.IFS(OR($W64="Yes",$H64="Complete"),"Completed",$H64="On Hold","On Hold",$G64<0,"Overdue",$O64="Client","Waiting on Client",$G64<=7,"At Risk",TRUE(),"On Track")) | K64: =IF($A64="","",IFERROR(_xlfn.MAXIFS('Iteration Tracker'!$D$5:$D$124,'Iteration Tracker'!$A$5:$A$124,$A64),0)) | M64: =IF($A64="","",$L64-$K64) | R64: =IF($A64="","",IF($N64="","",TODAY()-$N64)) | Z64: =IF($A64="",0,IF(AND($G64<0,$J64<>"Completed",$J64<>"On Hold"),1,0)) -> 0 | AA64: =IF($A64="",0,IF(AND($G64>=0,$G64<=7,$J64<>"Completed",$J64<>"On Hold"),1,0)) -> 0 | AB64: =IF($A64="",0,IF(AND($O64="Us",$J64<>"Completed"),1,0)) -> 0 | AC64: =IF($A64="",0,IF(AND($H64="Awaiting Feedback",$R64<>"",$R64>7),1,0)) -> 0 | AD64: =IF($A64="",0,IF(AND($M64<>"",$M64<=1,$J64<>"Completed"),1,0)) -> 0 | AE64: =IFERROR(IF(AND($A64<>"",INDEX('Project Financials'!$AC$5:$AC$64,MATCH($A64,'Project Financials'!$A$5:$A$64,0))<0.2,INDEX('Project Financials'!$D$5:$D$64,MATCH($A64,'Project Financials'!$A$5:$A$64,0))>0),1,0),0) -> 0 | AF64: =IFERROR(IF(OR(INDEX(Payments!$N$5:$N$64,MATCH($A64,Payments!$B$5:$B$64,0))="Overdue",INDEX(Payments!$N$5:$N$64,MATCH($A64,Payments!$B$5:$B$64,0))="Awaiting Deposit"),1,0),0) -> 0 | AG64: =IF($A64="",0,IF(SUM(Z64:AF64)>0,1,0)) -> 0 | AH64: =IF($AG64=0,"",LEFT((IF($Z64=1,"Overdue; ",""))&(IF($AA64=1,"Deadline ≤ 7 days; ",""))&(IF($AB64=1,"Action needed from us; ",""))&(IF($AC64=1,"Client feedback overdue; ",""))&(IF($AD64=1,"At iteration limit; ",""))&(IF($AE64=1,"Low margin; ",""))&(IF($AF64=1,"Unpaid invoice; ","")),LEN((IF($Z64=1,"Overdue; ",""))&(IF($AA64=1,"Deadline ≤ 7 days; ",""))&(IF($AB64=1,"Action needed from us; ",""))&(IF($AC64=1,"Client feedback overdue; ",""))&(IF($AD64=1,"At iteration limit; ",""))&(IF($AE64=1,"Low margin; ",""))&(IF($AF64=1,"Unpaid invoice; ","")))-2)) | AI64: =IF(AND($A64<>"",$J64<>"Completed",$J64<>"On Hold"),$F64*1000+(ROW()-ROW($A$5)+1),"") | AJ64: =IF($AG64=1,ROW()-ROW($A$5)+1,"")

Sheet Client Brief
A1: CLIENT BRIEF — Creative Brief Database
A2: Client Direction • Olfactive Direction • My Creative Interpretation. One row per fragrance, linked by Project ID.
B3: INPUT — type or choose here | F3: CALCULATED — formula, do not edit | J3: AUTO-LOOKUP — pulled from another sheet
A4: Project ID | B4: Client | C4: Fragrance | D4: Target Customer | E4: Gender Positioning | F4: Target Age | G4: Intended Market | H4: Desired Retail Price | I4: Desired Concentration | J4: Bottle Size | K4: Product Type | L4: Client Description | M4: Overall Feeling | N4: Desired Opening | O4: Desired Heart | P4: Desired Drydown | Q4: Top Notes Requested | R4: Heart Notes Requested | S4: Base Notes Requested | T4: Preferred Fragrance Families | U4: Reference Perfumes | V4: Materials/Notes They Like | W4: Materials/Notes They Dislike | X4: Must Include | Y4: Must Avoid | Z4: Desired Strength | AA4: Desired Projection | AB4: Desired Longevity | AC4: Season | AD4: Occasion | AE4: Day/Night | AF4: Commercial vs Artistic | AG4: What I Think The Client Actually Wants | AH4: Proposed DNA | AI4: Recommended Top Direction | AJ4: Recommended Heart Direction | AK4: Recommended Base Direction | AL4: Suggested Materials | AM4: Suggested Accords | AN4: Potential Reference Structures | AO4: Creative Twist | AP4: Potential Problems With Brief | AQ4: Questions To Ask Client | AR4: Development Strategy
B5: =IF($A5="","",IFERROR(INDEX('Fragrance Projects'!$C$5:$C$64,MATCH($A5,'Fragrance Projects'!$A$5:$A$64,0)),"")) | C5: =IF($A5="","",IFERROR(INDEX('Fragrance Projects'!$D$5:$D$64,MATCH($A5,'Fragrance Projects'!$A$5:$A$64,0)),""))
B6: =IF($A6="","",IFERROR(INDEX('Fragrance Projects'!$C$5:$C$64,MATCH($A6,'Fragrance Projects'!$A$5:$A$64,0)),"")) | C6: =IF($A6="","",IFERROR(INDEX('Fragrance Projects'!$D$5:$D$64,MATCH($A6,'Fragrance Projects'!$A$5:$A$64,0)),""))
B7: =IF($A7="","",IFERROR(INDEX('Fragrance Projects'!$C$5:$C$64,MATCH($A7,'Fragrance Projects'!$A$5:$A$64,0)),"")) | C7: =IF($A7="","",IFERROR(INDEX('Fragrance Projects'!$D$5:$D$64,MATCH($A7,'Fragrance Projects'!$A$5:$A$64,0)),""))
B8: =IF($A8="","",IFERROR(INDEX('Fragrance Projects'!$C$5:$C$64,MATCH($A8,'Fragrance Projects'!$A$5:$A$64,0)),"")) | C8: =IF($A8="","",IFERROR(INDEX('Fragrance Projects'!$D$5:$D$64,MATCH($A8,'Fragrance Projects'!$A$5:$A$64,0)),""))
B9: =IF($A9="","",IFERROR(INDEX('Fragrance Projects'!$C$5:$C$64,MATCH($A9,'Fragrance Projects'!$A$5:$A$64,0)),"")) | C9: =IF($A9="","",IFERROR(INDEX('Fragrance Projects'!$D$5:$D$64,MATCH($A9,'Fragrance Projects'!$A$5:$A$64,0)),""))
B10: =IF($A10="","",IFERROR(INDEX('Fragrance Projects'!$C$5:$C$64,MATCH($A10,'Fragrance Projects'!$A$5:$A$64,0)),"")) | C10: =IF($A10="","",IFERROR(INDEX('Fragrance Projects'!$D$5:$D$64,MATCH($A10,'Fragrance Projects'!$A$5:$A$64,0)),""))
B11: =IF($A11="","",IFERROR(INDEX('Fragrance Projects'!$C$5:$C$64,MATCH($A11,'Fragrance Projects'!$A$5:$A$64,0)),"")) | C11: =IF($A11="","",IFERROR(INDEX('Fragrance Projects'!$D$5:$D$64,MATCH($A11,'Fragrance Projects'!$A$5:$A$64,0)),""))
B12: =IF($A12="","",IFERROR(INDEX('Fragrance Projects'!$C$5:$C$64,MATCH($A12,'Fragrance Projects'!$A$5:$A$64,0)),"")) | C12: =IF($A12="","",IFERROR(INDEX('Fragrance Projects'!$D$5:$D$64,MATCH($A12,'Fragrance Projects'!$A$5:$A$64,0)),""))
B13: =IF($A13="","",IFERROR(INDEX('Fragrance Projects'!$C$5:$C$64,MATCH($A13,'Fragrance Projects'!$A$5:$A$64,0)),"")) | C13: =IF($A13="","",IFERROR(INDEX('Fragrance Projects'!$D$5:$D$64,MATCH($A13,'Fragrance Projects'!$A$5:$A$64,0)),""))
B14: =IF($A14="","",IFERROR(INDEX('Fragrance Projects'!$C$5:$C$64,MATCH($A14,'Fragrance Projects'!$A$5:$A$64,0)),"")) | C14: =IF($A14="","",IFERROR(INDEX('Fragrance Projects'!$D$5:$D$64,MATCH($A14,'Fragrance Projects'!$A$5:$A$64,0)),""))
B15: =IF($A15="","",IFERROR(INDEX('Fragrance Projects'!$C$5:$C$64,MATCH($A15,'Fragrance Projects'!$A$5:$A$64,0)),"")) | C15: =IF($A15="","",IFERROR(INDEX('Fragrance Projects'!$D$5:$D$64,MATCH($A15,'Fragrance Projects'!$A$5:$A$64,0)),""))
B16: =IF($A16="","",IFERROR(INDEX('Fragrance Projects'!$C$5:$C$64,MATCH($A16,'Fragrance Projects'!$A$5:$A$64,0)),"")) | C16: =IF($A16="","",IFERROR(INDEX('Fragrance Projects'!$D$5:$D$64,MATCH($A16,'Fragrance Projects'!$A$5:$A$64,0)),""))
... B64: =IF($A64="","",IFERROR(INDEX('Fragrance Projects'!$C$5:$C$64,MATCH($A64,'Fragrance Projects'!$A$5:$A$64,0)),"")) | C64: =IF($A64="","",IFERROR(INDEX('Fragrance Projects'!$D$5:$D$64,MATCH($A64,'Fragrance Projects'!$A$5:$A$64,0)),""))

Sheet Iteration Tracker
A1: ITERATION TRACKER — Every Formula Version
A2: One row per iteration/version. Total Iteration Cost and per-project cost totals are calculated automatically.
B3: INPUT — type or choose here | F3: CALCULATED — formula, do not edit | J3: AUTO-LOOKUP — pulled from another sheet
A4: Project ID | B4: Client | C4: Fragrance | D4: Iteration No. | E4: Formula Version | F4: Date Created | G4: Date Compounded | H4: Date Evaluated | I4: Sample Sent Date | J4: Sample Received Date | K4: Feedback Received Date | L4: Client Rating /10 | M4: My Rating /10 | N4: Client Feedback | O4: My Evaluation | P4: Changes Required | Q4: Changes Made | R4: Next Version Required? | S4: Approved? | T4: Time Spent (hrs) | U4: Material Cost | V4: Shipping Cost | W4: Other Cost | X4: Total Iteration Cost
B5: =IF($A5="","",IFERROR(INDEX('Fragrance Projects'!$C$5:$C$64,MATCH($A5,'Fragrance Projects'!$A$5:$A$64,0)),"")) | C5: =IF($A5="","",IFERROR(INDEX('Fragrance Projects'!$D$5:$D$64,MATCH($A5,'Fragrance Projects'!$A$5:$A$64,0)),"")) | X5: =IF($A5="","",SUM($U5:$W5))
B6: =IF($A6="","",IFERROR(INDEX('Fragrance Projects'!$C$5:$C$64,MATCH($A6,'Fragrance Projects'!$A$5:$A$64,0)),"")) | C6: =IF($A6="","",IFERROR(INDEX('Fragrance Projects'!$D$5:$D$64,MATCH($A6,'Fragrance Projects'!$A$5:$A$64,0)),"")) | X6: =IF($A6="","",SUM($U6:$W6))
